Workbook

Sheet DATA
B1: CEPAL | AP1: PWT
B2: ARGENTINA | J2: BOLIVIA | R2: ECUADOR | Z2: NICARAGUA | AH2: VENEZUELA | AP2: ARGENTINA | AX2: BOLIVIA | BF2: ECUADOR | BN2: NICARAGUA | BV2: VENEZUELA
B3: GDP per capita | C3: Real wages | D3: Fx black market | E3: Gov. Revenue (%GDP) | F3: Gov. Revenue (%GDP) (including social contributions) | G3: Gov. Spending (%GDP) | H3: Budget deficit | I3: Reserves | J3: GDP per capita | K3: Real wages | L3: Fx black market | M3: Gov. Revenue (%GDP) | N3: Gov. Revenue (%GDP) (including social contributions) | O3: Gov. Spending (%GDP) | P3: Budget deficit | Q3: Reserves | R3: GDP per capita | S3: Real wages | T3: Fx black market | U3: Gov. Revenue (%GDP) | V3: Gov. Revenue (%GDP) (including social contributions) | W3: Gov. Spending (%GDP) | X3: Budget deficit | Y3: Reserves | Z3: GDP per capita | AA3: Real wages | AB3: Fx black market | AC3: Gov. Revenue (%GDP) | AD3: Gov. Revenue (%GDP) (including social contributions) | AE3: Gov. Spending (%GDP) | AF3: Budget deficit | AG3: Reserves | AH3: GDP per capita | AI3: Real wages | AJ3: Fx black market | AK3: Gov. Revenue (%GDP) | AL3: Gov. Revenue (%GDP) (including social contributions) | AM3: Gov. Spending (%GDP) | AN3: Budget deficit | AO3: Reserves | AP3: GDP per capita | AQ3: Real wages | AR3: Fx black market | AS3: Gov. Revenue | AT3: Gov. Spending | AU3: Budget deficit | AV3: Inflation | AW3: Reserves | AX3: GDP per capita | AY3: Real wages | AZ3: Fx black market | BA3: Gov. Revenue | BB3: Gov. Spending | BC3: Budget deficit | BD3: Inflation | BE3: Reserves | BF3: GDP per capita | BG3: Real wages | BH3: Fx black market | BI3: Gov. Revenue | BJ3: Gov. Spending | BK3: Budget deficit | BL3: Inflation | BM3: Reserves | BN3: GDP per capita | BO3: Real wages | BP3: Fx black market | BQ3: Gov. Revenue | BR3: Gov. Spending | BS3: Budget deficit | BT3: Inflation | BU3: Reserves | BV3: GDP per capita | BW3: Real wages | BX3: Fx black market | BY3: Gov. Revenue | BZ3: Gov. Spending | CA3: Budget deficit | CB3: Inflation | CC3: Reserves
A4: 1995 | B4: CEPAL offers it only in USD | C4: This info is not in the CEPAL web | D4: This info is not in the CEPAL web | E4: 7.5 | F4: 11.9 | G4: 15 | H4: Cepal doesn't have this info either. | I4: Cepal doesn't have this info either. | J4: CEPAL offers it only in USD | K4: This info is not in the CEPAL web | L4: This info is not in the CEPAL web | M4: 13.1 | N4: 14.3 | O4: 25 | P4: Cepal doesn't have this info either. | Q4: Cepal doesn't have this info either. | R4: CEPAL offers it only in USD | S4: This info is not in the CEPAL web | T4: This info is not in the CEPAL web | U4: 6.1 | V4: 8.2 | W4: NA | X4: Cepal doesn't have this info either. | Y4: Cepal doesn't have this info either. | Z4: CEPAL offers it only in USD | AA4: This info is not in the CEPAL web | AB4: This info is not in the CEPAL web | AC4: 9.4 | AD4: 11.1 | AE4: NA | AF4: Cepal doesn't have this info either. | AG4: Cepal doesn't have this info either. | AH4: CEPAL offers it only in USD | AI4: This info is not in the CEPAL web | AJ4: This info is not in the CEPAL web | AK4: 12.6 | AL4: 13.3 | AM4: NA | AN4: Cepal doesn't have this info either. | AO4: Cepal doesn't have this info either. | AP4: 17106.521 | AQ4: 19830.379 | AR4: 0.99975 | AT4: 87658.566 | AW4: 1.5979454e+10 | AX4: 4902.2253 | AY4: 5910.4458 | AZ4: 4.8003417 | BB4: 11241.852 | BD4: 10.193207 | BE4: 1.0054828e+09 | BF4: 8424.483 | BG4: 9015.8599 | BH4: 1 | BJ4: 25283.871 | BL4: 22.886133 | BM4: 1.7877822e+09 | BN4: 3187.8353 | BO4: 6525.3358 | BP4: 7.5455917 | BR4: 2039.8193 | BU4: 1.4200367e+08 | BV4: 586.20799 | BW4: 708.66111 | BX4: 0.17684167 | BZ4: 3743.1464 | CC4: 1.0715242e+10
A5: 1996 | E5: 7.5 | F5: 11.1 | G5: 15 | M5: 13 | N5: 15.3 | O5: 26 | U5: 5.5 | V5: 7.3 | W5: NA | AC5: 9.5 | AD5: 11.2 | AE5: NA | AK5: 13.8 | AL5: 14.2 | AM5: NA | AP5: 17837.753 | AQ5: 19009.441 | AR5: 0.9996625 | AT5: 130057.96 | AW5: 1.9719017e+10 | AX5: 5012.9296 | AY5: 6223.9359 | AZ5: 5.0746125 | BB5: 11658.311 | BD5: 12.425487 | BE5: 1.3016612e+09 | BF5: 8388.7826 | BG5: 8956.8405 | BH5: 1 | BJ5: 23824.609 | BL5: 24.373089 | BM5: 2.0113601e+09 | BN5: 3326.2063 | BO5: 6597.7506 | BP5: 8.4355 | BR5: 2012.3917 | BU5: 2.0286323e+08 | BV5: 573.16822 | BW5: 693.50128 | BX5: 0.41735 | BZ5: 3396.8647 | CC5: 1.6019844e+10
A6: 1997 | E6: 8.1 | F6: 11.6 | G6: 14 | M6: 13.6 | N6: 16.1 | O6: 27 | U6: 6.3 | V6: 7.9 | W6: NA | AC6: 10.6 | AD6: 12.3 | AE6: NA | AK6: 17.3 | AL6: 17.6 | AM6: 23 | AP6: 19062.272 | AQ6: 19006.541 | AR6: 0.9995 | AT6: 120479.32 | AW6: 2.24246e+10 | AX6: 5156.4249 | AY6: 6412.4892 | AZ6: 5.2542583 | BB6: 11408.974 | BD6: 4.7084444 | BE6: 1.3590513e+09 | BF6: 8570.0276 | BG6: 9053.5285 | BH6: 1 | BJ6: 23468.321 | BL6: 30.64298 | BM6: 2.2129627e+09 | BN6: 3396.4826 | BO6: 6468.3929 | BP6: 9.4480833 | BR6: 2029.6937 | BU6: 3.82292e+08 | BV6: 597.61508 | BW6: 696.04941 | BX6: 0.48863333 | BZ6: 3356.0167 | CC6: 1.7703783e+10
A7: 1998 | E7: 8.3 | F7: 11.6 | G7: 14 | M7: 14.7 | N7: 16.3 | O7: 29 | U7: 7.3 | V7: 8.9 | W7: NA | AC7: 11 | AD7: 13.1 | AE7: 14 | AK7: 12.2 | AL7: 12.9 | AM7: 22 | AP7: 19573.324 | AQ7: 19539.698 | AR7: 0.9995 | AT7: 112726.32 | AW7: 2.4855741e+10 | AX7: 5309.2049 | AY7: 6299.6306 | AZ7: 5.5101333 | BB7: 11098.141 | BD7: 7.673229 | BE7: 1.2188669e+09 | BF7: 8670.7738 | BG7: 9138.0294 | BH7: 1 | BJ7: 21349.263 | BL7: 36.098433 | BM7: 1.7389098e+09 | BN7: 3463.021 | BO7: 6373.9393 | BP7: 10.581917 | BR7: 2134.1942 | BU7: 3.5472289e+08 | BV7: 587.76925 | BW7: 745.74717 | BX7: 0.54756667 | BZ7: 3189.3718 | CC7: 1.4728841e+10
A8: 1999 | E8: 8.4 | F8: 11.5 | G8: 16 | M8: 13.7 | N8: 15.7 | O8: 29 | U8: 8.4 | V8: 9.6 | W8: NA | AC8: 10.7 | AD8: 12.8 | AE8: 18 | AK8: 13 | AL8: 13.8 | AM8: 22 | AP8: 18701.301 | AQ8: 19835.144 | AR8: 0.9995 | AT8: 105391.3 | AW8: 2.6350163e+10 | AX8: 5228.3549 | AY8: 6464.6114 | AZ8: 5.8124083 | BB8: 10588.415 | BD8: 2.1595163 | BE8: 1.2485801e+09 | BF8: 8098.0724 | BG8: 9679.3382 | BH8: 1 | BJ8: 19422.01 | BL8: 52.242351 | BM8: 1.8876305e+09 | BN8: 3646.9725 | BO8: 6369.9942 | BP8: 11.80925 | BR8: 2445.5803 | BU8: 5.1406751e+08 | BV8: 542.17028 | BW8: 681.89328 | BX8: 0.605725 | BZ8: 2464.1614 | CC8: 1.511015e+10
A9: 2000 | E9: 8.9 | F9: 11.9 | G9: 16 | M9: 15.2 | N9: 16.5 | O9: 29 | U9: 10.2 | V9: 11.4 | W9: 17 | AC9: 10.6 | AD9: 13.2 | AE9: 17 | AK9: 12.9 | AL9: 13.6 | AM9: 27 | AP9: 18350.671 | AQ9: 19459.987 | AR9: 0.9995 | AT9: 95760.693 | AW9: 2.5152117e+10 | AX9: 5256.8458 | AY9: 6751.2914 | AZ9: 6.1835417 | BB9: 10215.255 | BD9: 4.60823 | BE9: 1.1841082e+09 | BF9: 8032.1917 | BG9: 9560.5922 | BH9: 1 | BJ9: 18035.476 | BL9: 96.094114 | BM9: 1.1789585e+09 | BN9: 3737.9437 | BO9: 6254.9641 | BP9: 12.684392 | BR9: 2611.8386 | BT9: 7.0699135 | BU9: 4.9248508e+08 | BV9: 551.64301 | BW9: 620.09123 | BX9: 0.67996667 | BZ9: 2028.4439 | CC9: 1.5898851e+10
A10: 2001 | E10: 8.6 | F10: 11.5 | G10: 16 | M10: 14.4 | N10: 15.6 | O10: 32 | U10: 10.9 | V10: 12.8 | W10: 18 | AC10: 9.8 | AD10: 12.7 | AE10: 16 | AK10: 11.4 | AL10: 12.2 | AM10: 29 | AP10: 17351.093 | AQ10: 19145.558 | AR10: 0.9995 | AT10: 87268.169 | AW10: 1.4555553e+10 | AX10: 5244.455 | AY10: 6767.4124 | AZ10: 6.6069167 | BB10: 9604.9075 | BD10: 1.5896538 | BE10: 1.1460237e+09 | BF10: 8203.6511 | BG10: 9902.3931 | BH10: 1 | BJ10: 16021.195 | BL10: 37.678021 | BM10: 1.0735333e+09 | BN10: 3791.7242 | BO10: 6248.6627 | BP10: 13.371942 | BR10: 2675.0322 | BT10: 5.9860419 | BU10: 3.8402195e+08 | BV10: 559.86021 | BW10: 653.68612 | BX10: 0.72365833 | BZ10: 2186.7945 | CC10: 1.22644e+10
A11: 2002 | E11: 8.3 | F11: 10.8 | G11: 13 | M11: 14.6 | N11: 15.9 | O11: 33 | U11: 10.8 | V11: 13.5 | W11: 15 | AC11: 10.4 | AD11: 13.4 | AE11: 16 | AK11: 10.6 | AL11: 11.2 | AM11: 24 | AP11: 15294.158 | AQ11: 13644.503 | AR11: 3.0632567 | AT11: 78876.035 | AW11: 1.0492425e+10 | AX11: 5274.8606 | AY11: 6714.9261 | AZ11: 7.17 | BB11: 9063.5016 | BD11: 0.92825885 | BE11: 8.9272914e+08 | BF11: 8391.0789 | BG11: 10485.908 | BH11: 1 | BJ11: 14546.124 | BL11: 12.484019 | BM11: 1.0044028e+09 | BN11: 3766.1749 | BO11: 6124.1123 | BP11: 14.251325 | BR11: 2741.8993 | BT11: 3.7501747 | BU11: 4.5320584e+08 | BV11: 501.05226 | BW11: 530.59431 | BX11: 1.16095 | BZ11: 1864.6031 | CC11: 1.2106511e+10
A12: 2003 | E12: 10.5 | F12: 12.6 | G12: 14 | M12: 14.1 | N12: 15.4 | O12: 32 | U12: 10 | V12: 12.7 | W12: 15 | AC12: 11.7 | AD12: 14.8 | AE12: 19 | AK12: 11.3 | AL12: 11.9 | AM12: 27 | AP12: 16468.223 | AQ12: 13826.707 | AR12: 2.9006292 | AT12: 76868.31 | AW12: 1.4157284e+10 | AX12: 5318.7133 | AY12: 6939.8428 | AZ12: 7.6591667 | BB12: 8884.3553 | BD12: 3.337275 | BE12: 1.0969414e+09 | BF12: 8473.7164 | BG12: 10942.61 | BH12: 1 | BJ12: 13903.246 | BL12: 7.92941 | BM12: 1.1653404e+09 | BN12: 3808.0025 | BO12: 6110.916 | BP12: 15.104643 | BR12: 2959.0137 | BT12: 5.3023877 | BU12: 5.0823635e+08 | BV12: 454.03272 | BW12: 438.4893 | BX12: 1.6069583 | BZ12: 1804.6658 | CC12: 2.082056e+10
A13: 2004 | E13: 11.9 | F13: 14.2 | G13: 13 | M13: 16.3 | N13: 17.6 | O13: 32 | U13: 10 | V13: 12.8 | W13: 15 | AC13: 12.2 | AD13: 15.3 | AE13: 17 | AK13: 12.7 | AL13: 13.3 | AM13: 26 | AP13: 17766.731 | AQ13: 14811.075 | AR13: 2.9233008 | AT13: 74725.202 | AW13: 1.9659592e+10 | AX13: 5440.9629 | AY13: 6546.4261 | AZ13: 7.9362667 | BB13: 8623.2246 | BD13: 4.4373808 | BE13: 1.2714229e+09 | BF13: 9016.6002 | BG13: 11354.863 | BH13: 1 | BJ13: 13631.18 | BL13: 2.7421813 | BM13: 1.439914e+09 | BN13: 3955.8596 | BO13: 6187.8543 | BP13: 15.937247 | BR13: 3194.7419 | BT13: 8.4702106 | BU13: 6.6819863e+08 | BV13: 527.8664 | BW13: 503.6583 | BX13: 1.8913333 | BZ13: 1813.3992 | CC13: 2.340805e+10
A14: 2005 | E14: 12.1 | F14: 14.5 | G14: 15 | M14: 17.7 | N14: 19 | O14: 33 | U14: 10.6 | V14: 13.3 | W14: 14 | AC14: 12.9 | AD14: 16.1 | AE14: 17 | AK14: 15.3 | AL14: 15.9 | AM14: 27 | AP14: 19140.008 | AQ14: 16020.629 | AR14: 2.9036575 | AT14: 78996.977 | AW14: 2.8081719e+10 | AX14: 5581.0487 | AY14: 6551.6997 | AZ14: 8.0660625 | BB14: 8473.9624 | BD14: 5.3932311 | BE14: 1.794985e+09 | BF14: 9336.1357 | BG14: 12042.493 | BH14: 1 | BJ14: 12882.566 | BL14: 2.4077698 | BM14: 2.1479446e+09 | BN14: 4069.3217 | BO14: 6217.9683 | BP14: 16.73333 | BR14: 3472.1956 | BT14: 9.5990999 | BU14: 7.2780775e+08 | BV14: 572.72892 | BW14: 516.08665 | BX14: 2.08975 | BZ14: 1708.2401 | CC14: 2.9802941e+10
A15: 2006 | E15: 11.9 | F15: 14.7 | G15: 15 | M15: 17.2 | N15: 18.3 | O15: 29 | U15: 10.9 | V15: 14.2 | W15: 14 | AC15: 13.7 | AD15: 17.2 | AE15: 18 | AK15: 15.6 | AL15: 16.3 | AM15: 31 | AP15: 20471.298 | AQ15: 17545.915 | AR15: 3.0543133 | AT15: 90554.221 | AW15: 3.2022297e+10 | AX15: 5747.2221 | AY15: 6190.3187 | AZ15: 8.0116167 | BB15: 8245.9519 | BD15: 4.282396 | BE15: 3.1939827e+09 | BF15: 9585.3417 | BG15: 12602.422 | BH15: 1 | BJ15: 13215.717 | BL15: 3.2987485 | BM15: 2.0264803e+09 | BN15: 4180.576 | BO15: 6302.2917 | BP15: 17.569998 | BR15: 3668.6912 | BT15: 9.1401997 | BU15: 9.2189181e+08 | BV15: 619.47942 | BW15: 569.6201 | BX15: 2.147 | BZ15: 1872.7964 | CC15: 3.6715128e+10
A16: 2007 | E16: 11.5 | F16: 15.6 | G16: 16 | M16: 17.8 | N16: 18.9 | O16: 30 | U16: 11.2 | V16: 14.8 | W16: 16 | AC16: 13.9 | AD16: 17.5 | AE16: 17 | AK16: 16 | AL16: 16.8 | AM16: 28 | AP16: 22093.493 | AQ16: 18859.561 | AR16: 3.0956488 | AT16: 109193.59 | AW16: 4.6149457e+10 | AX16: 5907.0678 | AY16: 6280.5788 | AZ16: 7.8512452 | BB16: 8091.7904 | BD16: 8.7056092 | BE16: 5.313632e+09 | BF16: 9632.7716 | BG16: 12831.094 | BH16: 1 | BJ16: 13831.098 | BL16: 2.2761848 | BM16: 3.520673e+09 | BN16: 4332.845 | BO16: 6448.0493 | BP16: 18.448506 | BR16: 3707.4843 | BT16: 11.126935 | BU16: 1.1033224e+09 | BV16: 663.88069 | BW16: 641.48324 | BX16: 2.147 | BZ16: 2193.4612 | CC16: 3.3759219e+10
A17: 2008 | E17: 12.4 | F17: 16.3 | G17: 17 | M17: 19.2 | N17: 20.3 | O17: 33 | U17: 11.2 | V17: 14.6 | W17: 21 | AC17: 13.2 | AD17: 16.9 | AE17: 17 | AK17: 13.4 | AL17: 14.1 | AM17: 27 | AP17: 22762.81 | AQ17: 21202.423 | AR17: 3.1441646 | AT17: 126681.1 | AW17: 4.638538e+10 | AX17: 6165.1207 | AY17: 6191.9056 | AZ17: 7.2383207 | BB17: 7608.38 | BD17: 14.006811 | BE17: 7.7197664e+09 | BF17: 10076.558 | BG17: 13825.823 | BH17: 1 | BJ17: 15072.964 | BL17: 8.4000959 | BM17: 4.4728546e+09 | BN17: 4420.5206 | BO17: 6642.5126 | BP17: 19.371896 | BR17: 4073.6879 | BT17: 19.826203 | BU17: 1.1408425e+09 | BV17: 689.10091 | BW17: 602.4992 | BX17: 2.147 | BZ17: 2214.9661 | CC17: 4.3065463e+10
A18: 2009 | E18: 11.4 | F18: 16.7 | G18: 20 | M18: 19.5 | N18: 20.7 | O18: 35 | U18: 12.1 | V18: 15.4 | W18: 23 | AC18: 13.1 | AD18: 17.2 | AE18: 18 | AK18: 13.3 | AL18: 14.3 | AM18: 27 | AP18: 21202.596 | AQ18: 21693.256 | AR18: 3.7101068 | AT18: 153793.73 | AW18: 4.8006989e+10 | AX18: 6266.8122 | AY18: 6761.4325 | AZ18: 7.02 | BB18: 7487.4539 | BD18: 3.3464542 | BE18: 8.5745792e+09 | BF18: 9969.9297 | BG18: 14070.383 | BH18: 1 | BJ18: 17614.348 | BL18: 5.1599683 | BM18: 3.7921222e+09 | BN18: 4216.8616 | BO18: 6284.3151 | BP18: 20.339482 | BR18: 4132.3153 | BT18: 3.6870016 | BU18: 1.5730823e+09 | BV18: 657.62947 | BW18: 685.61976 | BX18: 2.147 | BZ18: 2663.6159 | CB18: 27.080941 | CC18: 3.4317957e+10
A19: 2010 | E19: 11.9 | F19: 17.2 | G19: 20 | M19: 18.1 | N19: 19.3 | O19: 31 | U19: 12.2 | V19: 15.8 | W19: 23 | AC19: 13.7 | AD19: 18 | AE19: 17 | AK19: 10.9 | AL19: 11.9 | AM19: 22 | AP19: 23113.661 | AQ19: 23044.234 | AR19: 3.8962952 | AT19: 187205.36 | AW19: 5.220755e+10 | AX19: 6419.0454 | AY19: 6537.6288 | AZ19: 7.0166667 | BB19: 7081.1978 | BD19: 2.5032761 | BE19: 9.730684e+09 | BF19: 10158.652 | BG19: 14556.456 | BH19: 1 | BJ19: 18140.578 | BL19: 3.5543773 | BM19: 2.6224934e+09 | BN19: 4343.4564 | BO19: 6382.5701 | BP19: 21.356449 | BR19: 4370.1694 | BT19: 5.4551343 | BU19: 1.7989813e+09 | BV19: 638.52378 | BW19: 555.75092 | BX19: 2.5820603 | BZ19: 2436.4757 | CB19: 28.187465 | CC19: 2.9665474e+10
A20: 2011 | E20: 11.8 | F20: 17.1 | G20: 21 | M20: 19.6 | N20: 24.2 | O20: 34 | U20: 12.3 | V20: 17.3 | W20: 23 | AC20: 14.5 | AD20: 18.8 | AE20: 17 | AK20: 12 | AL20: 13 | AM20: 26 | AP20: 24249.536 | AQ20: 25642.086 | AR20: 4.1101396 | AT20: 231180.7 | AW20: 4.6265801e+10 | AX20: 6644.4124 | AY20: 6748.3689 | AZ20: 6.9369625 | BB20: 6979.708 | BD20: 9.8844642 | BE20: 1.1994673e+10 | BF20: 10790.627 | BG20: 15682.955 | BH20: 1 | BJ20: 19976.602 | BL20: 4.4745327 | BM20: 2.9579994e+09 | BN20: 4556.0381 | BO20: 6604.7 | BP20: 22.424271 | BR20: 4715.2235 | BT20: 8.082388 | BU20: 1.8922484e+09 | BV20: 654.87733 | BW20: 565.85366 | BX20: 4.2893 | BZ20: 2676.1296 | CB20: 26.090212 | CC20: 2.7934651e+10
A21: 2012 | E21: 12 | F21: 17.8 | G21: 21 | M21: 20.1 | N21: 25 | O21: 33 | U21: 13.8 | V21: 19.3 | W21: 24 | AC21: 15 | AD21: 19.4 | AE21: 17 | AK21: 13.3 | AL21: 14.3 | AM21: 29 | AP21: 23750.772 | AQ21: 27452.677 | AR21: 4.5369344 | AT21: 238965.1 | AW21: 4.3223271e+10 | AX21: 6873.8904 | AY21: 6879.107 | AZ21: 6.91 | BB21: 6398.2106 | BD21: 4.5156029 | BE21: 1.3924289e+10 | BF21: 11229.835 | BG21: 16524.836 | BH21: 1 | BJ21: 19635.204 | BL21: 5.1017218 | BM21: 2.4860361e+09 | BN21: 4787.538 | BO21: 6749.4482 | BP21: 23.546664 | BR21: 4828.6211 | BT21: 7.1935505 | BU21: 1.8872149e+09 | BV21: 680.57734 | BW21: 648.55444 | BX21: 4.2893 | BZ21: 2801.0983 | CB21: 21.068996 | CC21: 2.9468789e+10
A22: 2013 | E22: 11.5 | F22: 17.5 | G22: 22 | M22: 20.9 | N22: 25.8 | O22: 35 | U22: 14.3 | V22: 19.1 | W22: 27 | AC22: 15 | AD22: 19.7 | AE22: 17 | AK22: 13.5 | AL22: 14.4 | AM22: 32 | AP22: 24067.956 | AQ22: 28883.893 | AR22: 5.4593527 | AT22: 261670.76 | AW22: 3.053392e+10 | AX22: 7226.3537 | AY22: 7277.708 | AZ22: 6.91 | BB22: 7215.2975 | BD22: 5.7364002 | BE22: 1.4429069e+10 | BF22: 11610.219 | BG22: 16533.926 | BH22: 1 | BJ22: 21871.959 | BL22: 2.7217758 | BM22: 4.3458403e+09 | BN22: 4957.193 | BO22: 6914.9152 | BP22: 24.722764 | BR22: 5410.4763 | BT22: 7.1354679 | BU22: 1.9929608e+09 | BV22: 679.98663 | BW22: 635.41777 | BX22: 6.0479618 | BZ22: 3204.5438 | CB22: 40.639428 | CC22: 2.0275216e+10
A23: 2014 | E23: 11.6 | F23: 17.3 | G23: 25 | M23: 21.4 | N23: 26.9 | O23: 40 | U23: 14.1 | V23: 18.8 | W23: 26 | AC23: 15.3 | AD23: 20.2 | AE23: 18 | AK23: NA | AL23: NA | AM23: 37 | AP23: 23220.275 | AQ23: 27782.43 | AR23: 8.075276 | AT23: 266991.02 | AW23: 3.1410813e+10 | AX23: 7504.1174 | AY23: 7640.1738 | AZ23: 6.91 | BB23: 8315.7761 | BD23: 5.7666007 | BE23: 1.5129278e+10 | BF23: 11865.52 | BG23: 16822.865 | BH23: 1 | BJ23: 24097.763 | BL23: 3.5892202 | BM23: 3.9413571e+09 | BN23: 5126.5363 | BO23: 6998.3724 | BP23: 25.9589 | BR23: 5980.901 | BT23: 6.0359686 | BU23: 2.2761768e+09 | BV23: 647.80758 | BW23: 733.02848 | BX23: 8.3394935 | BZ23: 3599.7734 | CB23: 62.16865 | CC23: 2.1454894e+10
A24: 2015 | E24: 11.3 | F24: 17.2 | G24: 24 | M24: 22.1 | N24: 28.4 | O24: 41 | U24: 15.7 | V24: 20.8 | W24: 25 | AC24: 15.6 | AD24: 20.8 | AE24: 18 | AK24: NA | AL24: NA | AM24: NA | AP24: 23611.954 | AQ24: 27863.566 | AR24: 9.2331855 | AT24: 294208.77 | AW24: 2.5520566e+10 | AX24: 7750.4563 | AY24: 8349.9942 | AZ24: 6.91 | BB24: 10577.863 | BD24: 4.0596104 | BE24: 1.3049621e+10 | BF24: 11686.638 | BG24: 16485.431 | BH24: 1 | BJ24: 25767.246 | BL24: 3.9666462 | BM24: 2.4872766e+09 | BN24: 5302.7141 | BO24: 7200.0949 | BP24: 27.256845 | BR24: 6549.5562 | BT24: 3.99738 | BU24: 2.4922628e+09 | BV24: 606.72028 | BW24: 602.71019 | BX24: 17.509795 | BZ24: 3127.037 | CB24: 121.73809 | CC24: 1.5625329e+10
A25: 2016 | E25: 11.1 | F25: 17.1 | G25: 26 | M25: 20.3 | N25: 26.6 | O25: 35 | U25: 14.6 | V25: 19.4 | W25: 24 | AC25: 16.2 | AD25: 21.8 | AE25: 19 | AK25: NA | AL25: NA | AM25: NA | AP25: 22890.624 | AQ25: 27465.511 | AR25: 14.758175 | AT25: 287301.37 | AW25: 3.8414518e+10 | AX25: 7962.1999 | AY25: 8497.8695 | AZ25: 6.91 | BB25: 11226.634 | BD25: 3.6232143 | BE25: 1.0053627e+10 | BF25: 11347.956 | BG25: 16095.847 | BH25: 1 | BJ25: 26563.583 | BL25: 1.7282646 | BM25: 4.2155532e+09 | BN25: 5473.6752 | BO25: 7316.3748 | BP25: 28.620962 | BR25: 7148.7036 | BT25: 3.5231732 | BU25: 2.4477714e+09 | BV25: 507.22088 | BW25: 509.01632 | BX25: 73.003828 | BZ25: 3417.844 | CB25: 254.94853 | CC25: 1.015e+10
A26: 2017 | E26: 9.8 | F26: 15.7 | G26: 24 | M26: 18.3 | N26: 24.4 | O26: 34 | U26: 14.1 | V26: 19.3 | W26: 23 | AC26: 16.6 | AD26: 22.3 | AE26: 19 | AK26: NA | AL26: NA | AM26: NA | AP26: 23272.185 | AQ26: 27761.427 | AR26: 16.562707 | AT26: 227802.94 | AW26: 5.5314409e+10 | AX26: 8176.8668 | AY26: 8654.193 | AZ26: 6.91 | BB26: 11802.576 | BD26: 2.8227581 | BE26: 1.0245969e+10 | BF26: 11413.08 | BG26: 16008.865 | BH26: 1 | BJ26: 28058.449 | BL26: 0.41733559 | BM26: 2.1696979e+09 | BN26: 5654.6306 | BO26: 7460.8417 | BP26: 30.050941 | BR26: 7674.8985 | BT26: 3.8506717 | BU26: 2.7577856e+09 | BV26: 434.26075 | BW26: 439.55311 | BX26: 607.68822 | BZ26: 2751.2272 | CC26: 9.7940621e+09
A27: 2018 | E27: 9.1 | F27: 14.5 | G27: 23 | M27: 17.7 | N27: 23.7 | O27: 12 | U27: 15 | V27: 20.1 | W27: 22 | AC27: 15.7 | AD27: 21.7 | AE27: 20 | AK27: NA | AL27: NA | AM27: NA | AP27: 22477.7 | AQ27: 26936.097 | AR27: 28.094992 | AT27: 216377.12 | AW27: 6.6221502e+10 | AX27: 8401.9087 | AY27: 8801.2569 | AZ27: 6.91 | BB27: 12365.038 | BD27: 2.2720599 | BE27: 8.9296142e+09 | BF27: 11357.911 | BG27: 15843.318 | BH27: 1 | BJ27: 28953.246 | BL27: -0.22410325 | BM27: 2.158694e+09 | BN27: 5363.4982 | BO27: 7200.1195 | BP27: 31.553212 | BR27: 7783.2195 | BT27: 4.9472373 | BU27: 2.2611434e+09 | BV27: 355.27981 | BW27: 363.90051 | BX27: 388549.29 | BZ27: 2159.0286
A28: 2019 | E28: 9.7 | F28: 14.6 | G28: 22 | M28: 17.4 | N28: 23.6 | O28: NA | U28: 14 | V28: 19.5 | W28: 28 | AC28: 17.5 | AD28: 24.1 | AE28: 19 | AK28: NA | AL28: NA | AM28: NA | AP28: 21785.49 | AQ28: 25704.775 | AR28: 48.147892 | AT28: 218940.36 | AW28: 4.4880566e+10 | AX28: 8468.8332 | AY28: 8767.5343 | AZ28: 6.91 | BB28: 12882.094 | BD28: 1.839545 | BE28: 6.4554499e+09 | BF28: 11174.779 | BG28: 15701.851 | BH28: 1 | BJ28: 28651.72 | BL28: 0.26601252 | BM28: 2.9402351e+09 | BN28: 5092.4409 | BO28: 6912.0172 | BP28: 33.121745 | BR28: 7805.9036 | BT28: 5.3762899 | BU28: 2.3974447e+09 | BV28: 233.9387 | BW28: 244.47438 | BX28: 76369942 | BZ28: 1403.4667
A29: 2020 | E29: NA | F29: NA | G29: 26 | M29: 13.6 | N29: 19.6 | O29: NA | U29: 13.1 | V29: 19 | W29: 28 | AC29: 17.2 | AD29: 23.8 | AE29: 20 | AK29: NA | AL29: NA | AM29: NA | AP29: 0 | AW29: 3.9403735e+10 | BD29: 0.94074215 | BE29: 5.2472347e+09 | BL29: -0.33887239 | BM29: 6.5694605e+09 | BT29: 3.6818134 | BU29: 3.2119034e+09
A30: 2021 | E30: NA | F30: NA | G30: NA | M30: NA | N30: NA | O30: NA | U30: NA | V30: NA | W30: NA | AC30: NA | AD30: NA | AE30: NA | AK30: NA | AL30: NA | AM30: NA | AP30: 0

Sheet NX ENERGY

Sheet Variables
A1: Variable | B1: Description | C1: Source | D1: Link
A2: GDP per Capita | B2: Real GDP at constant 2017 national prices (in mil. 2017US$) / Population | C2: PWT
A3: Gov Spending | B3: Share of Government Consumption * Real GDP at constant 2017 national prices (in mil. 2017US$) | C3: PWT
A4: Real Wages | B4: Share of labour compensation in GDP at current national prices * Real GDP at constant 2017 national prices / Number of persons engaged (in millions) | C4: PWT
A5: Reserves | B5: Total reserves (includes gold, current US$) | C5: IMF | D5: https://data.worldbank.org/indicator/FI.RES.TOTL.CD
A6: Exchange Rate | B6: Exchange rate, national currency/USD (market+estimated) | C6: PWT
A7: Inflation | B7: Inflation, consumer prices (annual %) | C7: IMF | D7: https://data.worldbank.org/indicator/FP.CPI.TOTL.ZG
A8: Gov. Revenue (%GDP) | B8: Tax revenue is composed of compulsory transfers to the central government sector. (As a percentage of gross domestic product) | C8: CEPAL
A9: Gov. Spending(%GDP) | B9: Total expenditures of the central government as % of GDP | C9: CEPAL
A10: Gov. Revenue (%GDP) (including social contributions) | B10: Tax revenue is composed of compulsory transfers to the central government sector including social contributions. (As a percentage of gross domestic product) | C10: CEPAL

Sheet D&E

Sheet Complete
B1: PWT
B2: ARGENTINA | K2: BOLIVIA | T2: ECUADOR | AC2: NICARAGUA | AL2: VENEZUELA
B3: GDP per capita | C3: GDP | D3: Real wages | E3: Fx black market | F3: Gov. Revenue | G3: Gov. Spending | H3: Budget deficit | I3: Inflation | J3: Reserves | K3: GDP per capita | L3: GDP | M3: Real wages | N3: Fx black market | O3: Gov. Revenue | P3: Gov. Spending | Q3: Budget deficit | R3: Inflation | S3: Reserves | T3: GDP per capita | U3: GDP | V3: Real wages | W3: Fx black market | X3: Gov. Revenue | Y3: Gov. Spending | Z3: Budget deficit | AA3: Inflation | AB3: Reserves | AC3: GDP per capita | AD3: GDP | AE3: Real wages | AF3: Fx black market | AG3: Gov. Revenue | AH3: Gov. Spending | AI3: Budget deficit | AJ3: Inflation | AK3: Reserves | AL3: GDP per capita | AM3: GDP | AN3: Real wages | AO3: Fx black market | AP3: Gov. Revenue | AQ3: Gov. Spending | AR3: Budget deficit | AS3: Inflation | AT3: Reserves
A4: 1995 | B4: 17106.521 | C4: =[1]Data!$S397 -> 595788.81 | D4: 19830.379 | E4: 0.99975 | F4: =DATA!F4*C4/100 -> 70898.869 | G4: 87658.566 | H4: =F4-G4 -> -16759.698 | J4: 1.5979454e+10 | K4: 4902.2253 | L4: =[1]Data!$S1657 -> 37366.418 | M4: 5910.4458 | N4: 4.8003417 | O4: =DATA!N4*Complete!L4/100 -> 5343.3978 | P4: 11241.852 | Q4: =O4-P4 -> -5898.454 | R4: 10.193207 | S4: 1.0054828e+09 | T4: 8424.483 | U4: =[1]Data!$S3687 -> 96504.172 | V4: 9015.8599 | W4: 1 | X4: =U4*DATA!V4/100 -> 7913.3421 | Y4: 25283.871 | Z4: =X4-Y4 -> -17370.529 | AA4: 22.886133 | AB4: 1.7877822e+09 | AC4: 3187.8353 | AD4: =[1]Data!$S8797 -> 14830.399 | AE4: 6525.3358 | AF4: 7.5455917 | AG4: =AD4*DATA!AD4/100 -> 1646.1743 | AH4: 2039.8193 | AI4: =AG4-AH4 -> -393.64495 | AK4: 1.4200367e+08 | AL4: 586.20799 | AM4: =[1]Data!$S12367 -> 12856.177 | AN4: 708.66111 | AO4: 0.17684167 | AP4: =AM4*DATA!AL4/100 -> 1709.8715 | AQ4: 3743.1464 | AR4: =AP4-AQ4 -> -2033.2749 | AT4: 1.0715242e+10
A5: 1996 | B5: 17837.753 | C5: =[1]Data!$S398 -> 628716.12 | D5: 19009.441 | E5: 0.9996625 | F5: =DATA!F5*C5/100 -> 69787.49 | G5: 130057.96 | H5: =F5-G5 -> -60270.474 | J5: 1.9719017e+10 | K5: 5012.9296 | L5: =[1]Data!$S1658 -> 38996.918 | M5: 6223.9359 | N5: 5.0746125 | O5: =DATA!N5*Complete!L5/100 -> 5966.5284 | P5: 11658.311 | Q5: =O5-P5 -> -5691.7821 | R5: 12.425487 | S5: 1.3016612e+09 | T5: 8388.7826 | U5: =[1]Data!$S3688 -> 98175.383 | V5: 8956.8405 | W5: 1 | X5: =U5*DATA!V5/100 -> 7166.8029 | Y5: 23824.609 | Z5: =X5-Y5 -> -16657.806 | AA5: 24.373089 | AB5: 2.0113601e+09 | AC5: 3326.2063 | AD5: =[1]Data!$S8798 -> 15771.467 | AE5: 6597.7506 | AF5: 8.4355 | AG5: =AD5*DATA!AD5/100 -> 1766.4043 | AH5: 2012.3917 | AI5: =AG5-AH5 -> -245.9874 | AK5: 2.0286323e+08 | AL5: 573.16822 | AM5: =[1]Data!$S12368 -> 12830.743 | AN5: 693.50128 | AO5: 0.41735 | AP5: =AM5*DATA!AL5/100 -> 1821.9655 | AQ5: 3396.8647 | AR5: =AP5-AQ5 -> -1574.8992 | AT5: 1.6019844e+10
A6: 1997 | B6: 19062.272 | C6: =[1]Data!$S399 -> 679711.62 | D6: 19006.541 | E6: 0.9995 | F6: =DATA!F6*C6/100 -> 78846.548 | G6: 120479.32 | H6: =F6-G6 -> -41632.771 | J6: 2.24246e+10 | K6: 5156.4249 | L6: =[1]Data!$S1659 -> 40928.906 | M6: 6412.4892 | N6: 5.2542583 | O6: =DATA!N6*Complete!L6/100 -> 6589.5539 | P6: 11408.974 | Q6: =O6-P6 -> -4819.4203 | R6: 4.7084444 | S6: 1.3590513e+09 | T6: 8570.0276 | U6: =[1]Data!$S3689 -> 102424.27 | V6: 9053.5285 | W6: 1 | X6: =U6*DATA!V6/100 -> 8091.5176 | Y6: 23468.321 | Z6: =X6-Y6 -> -15376.804 | AA6: 30.64298 | AB6: 2.2129627e+09 | AC6: 3396.4826 | AD6: =[1]Data!$S8799 -> 16397.066 | AE6: 6468.3929 | AF6: 9.4480833 | AG6: =AD6*DATA!AD6/100 -> 2016.8392 | AH6: 2029.6937 | AI6: =AG6-AH6 -> -12.854537 | AK6: 3.82292e+08 | AL6: 597.61508 | AM6: =[1]Data!$S12369 -> 13648.18 | AN6: 696.04941 | AO6: 0.48863333 | AP6: =AM6*DATA!AL6/100 -> 2402.0796 | AQ6: 3356.0167 | AR6: =AP6-AQ6 -> -953.93706 | AT6: 1.7703783e+10
A7: 1998 | B7: 19573.324 | C7: =[1]Data!$S400 -> 705881.75 | D7: 19539.698 | E7: 0.9995 | F7: =DATA!F7*C7/100 -> 81882.283 | G7: 112726.32 | H7: =F7-G7 -> -30844.039 | J7: 2.4855741e+10 | K7: 5309.2049 | L7: =[1]Data!$S1660 -> 42987.363 | M7: 6299.6306 | N7: 5.5101333 | O7: =DATA!N7*Complete!L7/100 -> 7006.9402 | P7: 11098.141 | Q7: =O7-P7 -> -4091.2013 | R7: 7.673229 | S7: 1.2188669e+09 | T7: 8670.7738 | U7: =[1]Data!$S3690 -> 105769.99 | V7: 9138.0294 | W7: 1 | X7: =U7*DATA!V7/100 -> 9413.5293 | Y7: 21349.263 | Z7: =X7-Y7 -> -11935.734 | AA7: 36.098433 | AB7: 1.7389098e+09 | AC7: 3463.021 | AD7: =[1]Data!$S8800 -> 17005.674 | AE7: 6373.9393 | AF7: 10.581917 | AG7: =AD7*DATA!AD7/100 -> 2227.7433 | AH7: 2134.1942 | AI7: =AG7-AH7 -> 93.549054 | AK7: 3.5472289e+08 | AL7: 587.76925 | AM7: =[1]Data!$S12370 -> 13688.302 | AN7: 745.74717 | AO7: 0.54756667 | AP7: =AM7*DATA!AL7/100 -> 1765.7909 | AQ7: 3189.3718 | AR7: =AP7-AQ7 -> -1423.5809 | AT7: 1.4728841e+10
A8: 1999 | B8: 18701.301 | C8: =[1]Data!$S401 -> 681984.44 | D8: 19835.144 | E8: 0.9995 | F8: =DATA!F8*C8/100 -> 78428.21 | G8: 105391.3 | H8: =F8-G8 -> -26963.085 | J8: 2.6350163e+10 | K8: 5228.3549 | L8: =[1]Data!$S1661 -> 43170.871 | M8: 6464.6114 | N8: 5.8124083 | O8: =DATA!N8*Complete!L8/100 -> 6777.8268 | P8: 10588.415 | Q8: =O8-P8 -> -3810.5885 | R8: 2.1595163 | S8: 1.2485801e+09 | T8: 8098.0724 | U8: =[1]Data!$S3691 -> 100757.15 | V8: 9679.3382 | W8: 1 | X8: =U8*DATA!V8/100 -> 9672.6863 | Y8: 19422.01 | Z8: =X8-Y8 -> -9749.3238 | AA8: 52.242351 | AB8: 1.8876305e+09 | AC8: 3646.9725 | AD8: =[1]Data!$S8801 -> 18202.186 | AE8: 6369.9942 | AF8: 11.80925 | AG8: =AD8*DATA!AD8/100 -> 2329.8798 | AH8: 2445.5803 | AI8: =AG8-AH8 -> -115.70054 | AK8: 5.1406751e+08 | AL8: 542.17028 | AM8: =[1]Data!$S12371 -> 12871.036 | AN8: 681.89328 | AO8: 0.605725 | AP8: =AM8*DATA!AL8/100 -> 1776.203 | AQ8: 2464.1614 | AR8: =AP8-AQ8 -> -687.95841 | AT8: 1.511015e+10
A9: 2000 | B9: 18350.671 | C9: =[1]Data!$S402 -> 676603.69 | D9: 19459.987 | E9: 0.9995 | F9: =DATA!F9*C9/100 -> 80515.839 | G9: 95760.693 | H9: =F9-G9 -> -15244.854 | J9: 2.5152117e+10 | K9: 5256.8458 | L9: =[1]Data!$S1662 -> 44253.516 | M9: 6751.2914 | N9: 6.1835417 | O9: =DATA!N9*Complete!L9/100 -> 7301.8301 | P9: 10215.255 | Q9: =O9-P9 -> -2913.4245 | R9: 4.60823 | S9: 1.1841082e+09 | T9: 8032.1917 | U9: =[1]Data!$S3692 -> 101857.21 | V9: 9560.5922 | W9: 1 | X9: =U9*DATA!V9/100 -> 11611.722 | Y9: 18035.476 | Z9: =X9-Y9 -> -6423.754 | AA9: 96.094114 | AB9: 1.1789585e+09 | AC9: 3737.9437 | AD9: =[1]Data!$S8802 -> 18948.766 | AE9: 6254.9641 | AF9: 12.684392 | AG9: =AD9*DATA!AD9/100 -> 2501.2371 | AH9: 2611.8386 | AI9: =AG9-AH9 -> -110.60155 | AJ9: 7.0699135 | AK9: 4.9248508e+08 | AL9: 551.64301 | AM9: =[1]Data!$S12372 -> 13345.594 | AN9: 620.09123 | AO9: 0.67996667 | AP9: =AM9*DATA!AL9/100 -> 1815.0007 | AQ9: 2028.4439 | AR9: =AP9-AQ9 -> -213.44313 | AT9: 1.5898851e+10
A10: 2001 | B10: 17351.093 | C10: =[1]Data!$S403 -> 646773.31 | D10: 19145.558 | E10: 0.9995 | F10: =DATA!F10*C10/100 -> 74378.931 | G10: 87268.169 | H10: =F10-G10 -> -12889.238 | J10: 1.4555553e+10 | K10: 5244.455 | L10: =[1]Data!$S1663 -> 44998.656 | M10: 6767.4124 | N10: 6.6069167 | O10: =DATA!N10*Complete!L10/100 -> 7019.7904 | P10: 9604.9075 | Q10: =O10-P10 -> -2585.1171 | R10: 1.5896538 | S10: 1.1460237e+09 | T10: 8203.6511 | U10: =[1]Data!$S3693 -> 105947.42 | V10: 9902.3931 | W10: 1 | X10: =U10*DATA!V10/100 -> 13561.27 | Y10: 16021.195 | Z10: =X10-Y10 -> -2459.9248 | AA10: 37.678021 | AB10: 1.0735333e+09 | AC10: 3791.7242 | AD10: =[1]Data!$S8803 -> 19509.809 | AE10: 6248.6627 | AF10: 13.371942 | AG10: =AD10*DATA!AD10/100 -> 2477.7457 | AH10: 2675.0322 | AI10: =AG10-AH10 -> -197.28651 | AJ10: 5.9860419 | AK10: 3.8402195e+08 | AL10: 559.86021 | AM10: =[1]Data!$S12373 -> 13798.579 | AN10: 653.68612 | AO10: 0.72365833 | AP10: =AM10*DATA!AL10/100 -> 1683.4267 | AQ10: 2186.7945 | AR10: =AP10-AQ10 -> -503.3679 | AT10: 1.22644e+10
A11: 2002 | B11: 15294.158 | C11: =[1]Data!$S404 -> 576310.62 | D11: 13644.503 | E11: 3.0632567 | F11: =DATA!F11*C11/100 -> 62241.548 | G11: 78876.035 | H11: =F11-G11 -> -16634.488 | J11: 1.0492425e+10 | K11: 5274.8606 | L11: =[1]Data!$S1664 -> 46117.125 | M11: 6714.9261 | N11: 7.17 | O11: =DATA!N11*Complete!L11/100 -> 7332.6229 | P11: 9063.5016 | Q11: =O11-P11 -> -1730.8788 | R11: 0.92825885 | S11: 8.9272914e+08 | T11: 8391.0789 | U11: =[1]Data!$S3694 -> 110287.85 | V11: 10485.908 | W11: 1 | X11: =U11*DATA!V11/100 -> 14888.86 | Y11: 14546.124 | Z11: =X11-Y11 -> 342.73568 | AA11: 12.484019 | AB11: 1.0044028e+09 | AC11: 3766.1749 | AD11: =[1]Data!$S8804 -> 19656.902 | AE11: 6124.1123 | AF11: 14.251325 | AG11: =AD11*DATA!AD11/100 -> 2634.0249 | AH11: 2741.8993 | AI11: =AG11-AH11 -> -107.87438 | AJ11: 3.7501747 | AK11: 4.5320584e+08 | AL11: 501.05226 | AM11: =[1]Data!$S12374 -> 12576.616 | AN11: 530.59431 | AO11: 1.16095 | AP11: =AM11*DATA!AL11/100 -> 1408.581 | AQ11: 1864.6031 | AR11: =AP11-AQ11 -> -456.02207 | AT11: 1.2106511e+10
A12: 2003 | B12: 16468.223 | C12: =[1]Data!$S405 -> 627239.5 | D12: 13826.707 | E12: 2.9006292 | F12: =DATA!F12*C12/100 -> 79032.177 | G12: 76868.31 | H12: =F12-G12 -> 2163.8668 | J12: 1.4157284e+10 | K12: 5318.7133 | L12: =[1]Data!$S1665 -> 47367.52 | M12: 6939.8428 | N12: 7.6591667 | O12: =DATA!N12*Complete!L12/100 -> 7294.598 | P12: 8884.3553 | Q12: =O12-P12 -> -1589.7573 | R12: 3.337275 | S12: 1.0969414e+09 | T12: 8473.7164 | U12: =[1]Data!$S3695 -> 113290.86 | V12: 10942.61 | W12: 1 | X12: =U12*DATA!V12/100 -> 14387.939 | Y12: 13903.246 | Z12: =X12-Y12 -> 484.69292 | AA12: 7.92941 | AB12: 1.1653404e+09 | AC12: 3808.0025 | AD12: =[1]Data!$S8805 -> 20152.398 | AE12: 6110.916 | AF12: 15.104643 | AG12: =AD12*DATA!AD12/100 -> 2982.555 | AH12: 2959.0137 | AI12: =AG12-AH12 -> 23.54122 | AJ12: 5.3023877 | AK12: 5.0823635e+08 | AL12: 454.03272 | AM12: =[1]Data!$S12375 -> 11601.273 | AN12: 438.4893 | AO12: 1.6069583 | AP12: =AM12*DATA!AL12/100 -> 1380.5515 | AQ12: 1804.6658 | AR12: =AP12-AQ12 -> -424.11423 | AT12: 2.082056e+10
A13: 2004 | B13: 17766.731 | C13: =[1]Data!$S406 -> 683876.5 | D13: 14811.075 | E13: 2.9233008 | F13: =DATA!F13*C13/100 -> 97110.463 | G13: 74725.202 | H13: =F13-G13 -> 22385.261 | J13: 1.9659592e+10 | K13: 5440.9629 | L13: =[1]Data!$S1666 -> 49344.305 | M13: 6546.4261 | N13: 7.9362667 | O13: =DATA!N13*Complete!L13/100 -> 8684.5976 | P13: 8623.2246 | Q13: =O13-P13 -> 61.373019 | R13: 4.4373808 | S13: 1.2714229e+09 | T13: 9016.6002 | U13: =[1]Data!$S3696 -> 122593.2 | V13: 11354.863 | W13: 1 | X13: =U13*DATA!V13/100 -> 15691.929 | Y13: 13631.18 | Z13: =X13-Y13 -> 2060.7488 | AA13: 2.7421813 | AB13: 1.439914e+09 | AC13: 3955.8596 | AD13: =[1]Data!$S8806 -> 21222.93 | AE13: 6187.8543 | AF13: 15.937247 | AG13: =AD13*DATA!AD13/100 -> 3247.1082 | AH13: 3194.7419 | AI13: =AG13-AH13 -> 52.366336 | AJ13: 8.4702106 | AK13: 6.6819863e+08 | AL13: 527.8664 | AM13: =[1]Data!$S12376 -> 13722.729 | AN13: 503.6583 | AO13: 1.8913333 | AP13: =AM13*DATA!AL13/100 -> 1825.1229 | AQ13: 1813.3992 | AR13: =AP13-AQ13 -> 11.723697 | AT13: 2.340805e+10
A14: 2005 | B14: 19140.008 | C14: =[1]Data!$S407 -> 744411 | D14: 16020.629 | E14: 2.9036575 | F14: =DATA!F14*C14/100 -> 107939.6 | G14: 78996.977 | H14: =F14-G14 -> 28942.618 | J14: 2.8081719e+10 | K14: 5581.0487 | L14: =[1]Data!$S1667 -> 51525.949 | M14: 6551.6997 | N14: 8.0660625 | O14: =DATA!N14*Complete!L14/100 -> 9789.9304 | P14: 8473.9624 | Q14: =O14-P14 -> 1315.968 | R14: 5.3932311 | S14: 1.794985e+09 | T14: 9336.1357 | U14: =[1]Data!$S3697 -> 129079.98 | V14: 12042.493 | W14: 1 | X14: =U14*DATA!V14/100 -> 17167.638 | Y14: 12882.566 | Z14: =X14-Y14 -> 4285.072 | AA14: 2.4077698 | AB14: 2.1479446e+09 | AC14: 4069.3217 | AD14: =[1]Data!$S8807 -> 22131.779 | AE14: 6217.9683 | AF14: 16.73333 | AG14: =AD14*DATA!AD14/100 -> 3563.2165 | AH14: 3472.1956 | AI14: =AG14-AH14 -> 91.020867 | AJ14: 9.5990999 | AK14: 7.2780775e+08 | AL14: 572.72892 | AM14: =[1]Data!$S12377 -> 15138.627 | AN14: 516.08665 | AO14: 2.08975 | AP14: =AM14*DATA!AL14/100 -> 2407.0417 | AQ14: 1708.2401 | AR14: =AP14-AQ14 -> 698.80155 | AT14: 2.9802941e+10
A15: 2006 | B15: 20471.298 | C15: =[1]Data!$S408 -> 804314.81 | D15: 17545.915 | E15: 3.0543133 | F15: =DATA!F15*C15/100 -> 118234.28 | G15: 90554.221 | H15: =F15-G15 -> 27680.056 | J15: 3.2022297e+10 | K15: 5747.2221 | L15: =[1]Data!$S1668 -> 53997.715 | M15: 6190.3187 | N15: 8.0116167 | O15: =DATA!N15*Complete!L15/100 -> 9881.5818 | P15: 8245.9519 | Q15: =O15-P15 -> 1635.6299 | R15: 4.282396 | S15: 3.1939827e+09 | T15: 9585.3417 | U15: =[1]Data!$S3698 -> 134764 | V15: 12602.422 | W15: 1 | X15: =U15*DATA!V15/100 -> 19136.488 | Y15: 13215.717 | Z15: =X15-Y15 -> 5920.7715 | AA15: 3.2987485 | AB15: 2.0264803e+09 | AC15: 4180.576 | AD15: =[1]Data!$S8808 -> 23050.705 | AE15: 6302.2917 | AF15: 17.569998 | AG15: =AD15*DATA!AD15/100 -> 3964.7213 | AH15: 3668.6912 | AI15: =AG15-AH15 -> 296.03006 | AJ15: 9.1401997 | AK15: 9.2189181e+08 | AL15: 619.47942 | AM15: =[1]Data!$S12378 -> 16633.143 | AN15: 569.6201 | AO15: 2.147 | AP15: =AM15*DATA!AL15/100 -> 2711.2022 | AQ15: 1872.7964 | AR15: =AP15-AQ15 -> 838.40583 | AT15: 3.6715128e+10
A16: 2007 | B16: 22093.493 | C16: =[1]Data!$S409 -> 876764.69 | D16: 18859.561 | E16: 3.0956488 | F16: =DATA!F16*C16/100 -> 136775.29 | G16: 109193.59 | H16: =F16-G16 -> 27581.697 | J16: 4.6149457e+10 | K16: 5907.0678 | L16: =[1]Data!$S1669 -> 56462.348 | M16: 6280.5788 | N16: 7.8512452 | O16: =DATA!N16*Complete!L16/100 -> 10671.384 | P16: 8091.7904 | Q16: =O16-P16 -> 2579.5933 | R16: 8.7056092 | S16: 5.313632e+09 | T16: 9632.7716 | U16: =[1]Data!$S3699 -> 137715.47 | V16: 12831.094 | W16: 1 | X16: =U16*DATA!V16/100 -> 20381.889 | Y16: 13831.098 | Z16: =X16-Y16 -> 6550.7918 | AA16: 2.2761848 | AB16: 3.520673e+09 | AC16: 4332.845 | AD16: =[1]Data!$S8809 -> 24220.842 | AE16: 6448.0493 | AF16: 18.448506 | AG16: =AD16*DATA!AD16/100 -> 4238.6473 | AH16: 3707.4843 | AI16: =AG16-AH16 -> 531.16299 | AJ16: 11.126935 | AK16: 1.1033224e+09 | AL16: 663.88069 | AM16: =[1]Data!$S12379 -> 18089.162 | AN16: 641.48324 | AO16: 2.147 | AP16: =AM16*DATA!AL16/100 -> 3038.9792 | AQ16: 2193.4612 | AR16: =AP16-AQ16 -> 845.51799 | AT16: 3.3759219e+10
A17: 2008 | B17: 22762.81 | C17: =[1]Data!$S410 -> 912337.06 | D17: 21202.423 | E17: 3.1441646 | F17: =DATA!F17*C17/100 -> 148710.94 | G17: 126681.1 | H17: =F17-G17 -> 22029.837 | J17: 4.638538e+10 | K17: 6165.1207 | L17: =[1]Data!$S1670 -> 59933.938 | M17: 6191.9056 | N17: 7.2383207 | O17: =DATA!N17*Complete!L17/100 -> 12166.589 | P17: 7608.38 | Q17: =O17-P17 -> 4558.2093 | R17: 14.006811 | S17: 7.7197664e+09 | T17: 10076.558 | U17: =[1]Data!$S3700 -> 146470.22 | V17: 13825.823 | W17: 1 | X17: =U17*DATA!V17/100 -> 21384.652 | Y17: 15072.964 | Z17: =X17-Y17 -> 6311.6881 | AA17: 8.4000959 | AB17: 4.4728546e+09 | AC17: 4420.5206 | AD17: =[1]Data!$S8810 -> 25053 | AE17: 6642.5126 | AF17: 19.371896 | AG17: =AD17*DATA!AD17/100 -> 4233.957 | AH17: 4073.6879 | AI17: =AG17-AH17 -> 160.26912 | AJ17: 19.826203 | AK17: 1.1408425e+09 | AL17: 689.10091 | AM17: =[1]Data!$S12380 -> 19043.877 | AN17: 602.4992 | AO17: 2.147 | AP17: =AM17*DATA!AL17/100 -> 2685.1867 | AQ17: 2214.9661 | AR17: =AP17-AQ17 -> 470.22056 | AT17: 4.3065463e+10
A18: 2009 | B18: 21202.596 | C18: =[1]Data!$S411 -> 858340.19 | D18: 21693.256 | E18: 3.7101068 | F18: =DATA!F18*C18/100 -> 143342.81 | G18: 153793.73 | H18: =F18-G18 -> -10450.922 | J18: 4.8006989e+10 | K18: 6266.8122 | L18: =[1]Data!$S1671 -> 61946.066 | M18: 6761.4325 | N18: 7.02 | O18: =DATA!N18*Complete!L18/100 -> 12822.836 | P18: 7487.4539 | Q18: =O18-P18 -> 5335.3818 | R18: 3.3464542 | S18: 8.5745792e+09 | T18: 9969.9297 | U18: =[1]Data!$S3701 -> 147299.97 | V18: 14070.383 | W18: 1 | X18: =U18*DATA!V18/100 -> 22684.195 | Y18: 17614.348 | Z18: =X18-Y18 -> 5069.8475 | AA18: 5.1599683 | AB18: 3.7921222e+09 | AC18: 4216.8616 | AD18: =[1]Data!$S8811 -> 24228.088 | AE18: 6284.3151 | AF18: 20.339482 | AG18: =AD18*DATA!AD18/100 -> 4167.2311 | AH18: 4132.3153 | AI18: =AG18-AH18 -> 34.915828 | AJ18: 3.6870016 | AK18: 1.5730823e+09 | AL18: 657.62947 | AM18: =[1]Data!$S12381 -> 18434.018 | AN18: 685.61976 | AO18: 2.147 | AP18: =AM18*DATA!AL18/100 -> 2636.0645 | AQ18: 2663.6159 | AR18: =AP18-AQ18 -> -27.551356 | AS18: 27.080941 | AT18: 3.4317957e+10
A19: 2010 | B19: 23113.661 | C19: =[1]Data!$S412 -> 945250.56 | D19: 23044.234 | E19: 3.8962952 | F19: =DATA!F19*C19/100 -> 162583.1 | G19: 187205.36 | H19: =F19-G19 -> -24622.263 | J19: 5.220755e+10 | K19: 6419.0454 | L19: =[1]Data!$S1672 -> 64502.355 | M19: 6537.6288 | N19: 7.0166667 | O19: =DATA!N19*Complete!L19/100 -> 12448.955 | P19: 7081.1978 | Q19: =O19-P19 -> 5367.7568 | R19: 2.5032761 | S19: 9.730684e+09 | T19: 10158.652 | U19: =[1]Data!$S3702 -> 152492.72 | V19: 14556.456 | W19: 1 | X19: =U19*DATA!V19/100 -> 24093.85 | Y19: 18140.578 | Z19: =X19-Y19 -> 5953.2713 | AA19: 3.5543773 | AB19: 2.6224934e+09 | AC19: 4343.4564 | AD19: =[1]Data!$S8812 -> 25296.572 | AE19: 6382.5701 | AF19: 21.356449 | AG19: =AD19*DATA!AD19/100 -> 4553.383 | AH19: 4370.1694 | AI19: =AG19-AH19 -> 183.21366 | AJ19: 5.4551343 | AK19: 1.7989813e+09 | AL19: 638.52378 | AM19: =[1]Data!$S12382 -> 18159.578 | AN19: 555.75092 | AO19: 2.5820603 | AP19: =AM19*DATA!AL19/100 -> 2160.9898 | AQ19: 2436.4757 | AR19: =AP19-AQ19 -> -275.48586 | AS19: 28.187465 | AT19: 2.9665474e+10
A20: 2011 | B20: 24249.536 | C20: =[1]Data!$S413 -> 1002002.9 | D20: 25642.086 | E20: 4.1101396 | F20: =DATA!F20*C20/100 -> 171342.5 | G20: 231180.7 | H20: =F20-G20 -> -59838.195 | J20: 4.6265801e+10 | K20: 6644.4124 | L20: =[1]Data!$S1673 -> 67859.078 | M20: 6748.3689 | N20: 6.9369625 | O20: =DATA!N20*Complete!L20/100 -> 16421.897 | P20: 6979.708 | Q20: =O20-P20 -> 9442.1889 | R20: 9.8844642 | S20: 1.1994673e+10 | T20: 10790.627 | U20: =[1]Data!$S3703 -> 164491.06 | V20: 15682.955 | W20: 1 | X20: =U20*DATA!V20/100 -> 28456.954 | Y20: 19976.602 | Z20: =X20-Y20 -> 8480.3514 | AA20: 4.4745327 | AB20: 2.9579994e+09 | AC20: 4556.0381 | AD20: =[1]Data!$S8813 -> 26894.471 | AE20: 6604.7 | AF20: 22.424271 | AG20: =AD20*DATA!AD20/100 -> 5056.1605 | AH20: 4715.2235 | AI20: =AG20-AH20 -> 340.93694 | AJ20: 8.082388 | AK20: 1.8922484e+09 | AL20: 654.87733 | AM20: =[1]Data!$S12383 -> 18918.014 | AN20: 565.85366 | AO20: 4.2893 | AP20: =AM20*DATA!AL20/100 -> 2459.3418 | AQ20: 2676.1296 | AR20: =AP20-AQ20 -> -216.78778 | AS20: 26.090212 | AT20: 2.7934651e+10
A21: 2012 | B21: 23750.772 | C21: =[1]Data!$S414 -> 991718.12 | D21: 27452.677 | E21: 4.5369344 | F21: =DATA!F21*C21/100 -> 176525.83 | G21: 238965.1 | H21: =F21-G21 -> -62439.27 | J21: 4.3223271e+10 | K21: 6873.8904 | L21: =[1]Data!$S1674 -> 71335.008 | M21: 6879.107 | N21: 6.91 | O21: =DATA!N21*Complete!L21/100 -> 17833.752 | P21: 6398.2106 | Q21: =O21-P21 -> 11435.541 | R21: 4.5156029 | S21: 1.3924289e+10 | T21: 11229.835 | U21: =[1]Data!$S3704 -> 173771.59 | V21: 16524.836 | W21: 1 | X21: =U21*DATA!V21/100 -> 33537.918 | Y21: 19635.204 | Z21: =X21-Y21 -> 13902.713 | AA21: 5.1017218 | AB21: 2.4860361e+09 | AC21: 4787.538 | AD21: =[1]Data!$S8814 -> 28641.57 | AE21: 6749.4482 | AF21: 23.546664 | AG21: =AD21*DATA!AD21/100 -> 5556.4646 | AH21: 4828.6211 | AI21: =AG21-AH21 -> 727.8435 | AJ21: 7.1935505 | AK21: 1.8872149e+09 | AL21: 680.57734 | AM21: =[1]Data!$S12384 -> 19982.32 | AN21: 648.55444 | AO21: 4.2893 | AP21: =AM21*DATA!AL21/100 -> 2857.4718 | AQ21: 2801.0983 | AR21: =AP21-AQ21 -> 56.373534 | AS21: 21.068996 | AT21: 2.9468789e+10
A22: 2013 | B22: 24067.956 | C22: =[1]Data!$S415 -> 1015572.2 | D22: 28883.893 | E22: 5.4593527 | F22: =DATA!F22*C22/100 -> 177725.13 | G22: 261670.76 | H22: =F22-G22 -> -83945.625 | J22: 3.053392e+10 | K22: 7226.3537 | L22: =[1]Data!$S1675 -> 76182.945 | M22: 7277.708 | N22: 6.91 | O22: =DATA!N22*Complete!L22/100 -> 19655.2 | P22: 7215.2975 | Q22: =O22-P22 -> 12439.902 | R22: 5.7364002 | S22: 1.4429069e+10 | T22: 11610.219 | U22: =[1]Data!$S3705 -> 182367.22 | V22: 16533.926 | W22: 1 | X22: =U22*DATA!V22/100 -> 34832.139 | Y22: 21871.959 | Z22: =X22-Y22 -> 12960.179 | AA22: 2.7217758 | AB22: 4.3458403e+09 | AC22: 4957.193 | AD22: =[1]Data!$S8815 -> 30052.77 | AE22: 6914.9152 | AF22: 24.722764 | AG22: =AD22*DATA!AD22/100 -> 5920.3956 | AH22: 5410.4763 | AI22: =AG22-AH22 -> 509.91927 | AJ22: 7.1354679 | AK22: 1.9929608e+09 | AL22: 679.98663 | AM22: =[1]Data!$S12385 -> 20250.709 | AN22: 635.41777 | AO22: 6.0479618 | AP22: =AM22*DATA!AL22/100 -> 2916.1021 | AQ22: 3204.5438 | AR22: =AP22-AQ22 -> -288.44172 | AS22: 40.639428 | AT22: 2.0275216e+10
A23: 2014 | B23: 23220.275 | C23: =[1]Data!$S416 -> 990054.75 | D23: 27782.43 | E23: 8.075276 | F23: =DATA!F23*C23/100 -> 171279.47 | G23: 266991.02 | H23: =F23-G23 -> -95711.553 | J23: 3.1410813e+10 | K23: 7504.1174 | L23: =[1]Data!$S1676 -> 80342.961 | M23: 7640.1738 | N23: 6.91 | O23: =DATA!N23*Complete!L23/100 -> 21612.256 | P23: 8315.7761 | Q23: =O23-P23 -> 13296.48 | R23: 5.7666007 | S23: 1.5129278e+10 | T23: 11865.52 | U23: =[1]Data!$S3706 -> 189276.88 | V23: 16822.865 | W23: 1 | X23: =U23*DATA!V23/100 -> 35584.052 | Y23: 24097.763 | Z23: =X23-Y23 -> 11486.29 | AA23: 3.5892202 | AB23: 3.9413571e+09 | AC23: 5126.5363 | AD23: =[1]Data!$S8816 -> 31490.934 | AE23: 6998.3724 | AF23: 25.9589 | AG23: =AD23*DATA!AD23/100 -> 6361.1686 | AH23: 5980.901 | AI23: =AG23-AH23 -> 380.26757 | AJ23: 6.0359686 | AK23: 2.2761768e+09 | AL23: 647.80758 | AM23: =[1]Data!$S12386 -> 19462.062 | AN23: 733.02848 | AO23: 8.3394935 | AP23: =AM23*DATA!AL23/100 -> #VALUE! | AQ23: 3599.7734 | AR23: =AP23-AQ23 -> #VALUE! | AS23: 62.16865 | AT23: 2.1454894e+10
A24: 2015 | B24: 23611.954 | C24: =[1]Data!$S417 -> 1017094.8 | D24: 27863.566 | E24: 9.2331855 | F24: =DATA!F24*C24/100 -> 174940.3 | G24: 294208.77 | H24: =F24-G24 -> -119268.47 | J24: 2.5520566e+10 | K24: 7750.4563 | L24: =[1]Data!$S1677 -> 84245.367 | M24: 8349.9942 | N24: 6.91 | O24: =DATA!N24*Complete!L24/100 -> 23925.684 | P24: 10577.863 | Q24: =O24-P24 -> 13347.821 | R24: 4.0596104 | S24: 1.3049621e+10 | T24: 11686.638 | U24: =[1]Data!$S3707 -> 189464.02 | V24: 16485.431 | W24: 1 | X24: =U24*DATA!V24/100 -> 39408.515 | Y24: 25767.246 | Z24: =X24-Y24 -> 13641.269 | AA24: 3.9666462 | AB24: 2.4872766e+09 | AC24: 5302.7141 | AD24: =[1]Data!$S8817 -> 33000.062 | AE24: 7200.0949 | AF24: 27.256845 | AG24: =AD24*DATA!AD24/100 -> 6864.013 | AH24: 6549.5562 | AI24: =AG24-AH24 -> 314.45678 | AJ24: 3.99738 | AK24: 2.4922628e+09 | AL24: 606.72028 | AM24: =[1]Data!$S12387 -> 18251.256 | AN24: 602.71019 | AO24: 17.509795 | AP24: =AM24*DATA!AL24/100 -> #VALUE! | AQ24: 3127.037 | AR24: =AP24-AQ24 -> #VALUE! | AS24: 121.73809 | AT24: 1.5625329e+10
A25: 2016 | B25: 22890.624 | C25: =[1]Data!$S418 -> 995935.81 | D25: 27465.511 | E25: 14.758175 | F25: =DATA!F25*C25/100 -> 170305.02 | G25: 287301.37 | H25: =F25-G25 -> -116996.35 | J25: 3.8414518e+10 | K25: 7962.1999 | L25: =[1]Data!$S1678 -> 87837.508 | M25: 8497.8695 | N25: 6.91 | O25: =DATA!N25*Complete!L25/100 -> 23364.777 | P25: 11226.634 | Q25: =O25-P25 -> 12138.143 | R25: 3.6232143 | S25: 1.0053627e+10 | T25: 11347.956 | U25: =[1]Data!$S3708 -> 187140.45 | V25: 16095.847 | W25: 1 | X25: =U25*DATA!V25/100 -> 36305.248 | Y25: 26563.583 | Z25: =X25-Y25 -> 9741.6652 | AA25: 1.7282646 | AB25: 4.2155532e+09 | AC25: 5473.6752 | AD25: =[1]Data!$S8818 -> 34505.906 | AE25: 7316.3748 | AF25: 28.620962 | AG25: =AD25*DATA!AD25/100 -> 7522.2876 | AH25: 7148.7036 | AI25: =AG25-AH25 -> 373.58397 | AJ25: 3.5231732 | AK25: 2.4477714e+09 | AL25: 507.22088 | AM25: =[1]Data!$S12388 -> 15141.18 | AN25: 509.01632 | AO25: 73.003828 | AP25: =AM25*DATA!AL25/100 -> #VALUE! | AQ25: 3417.844 | AR25: =AP25-AQ25 -> #VALUE! | AS25: 254.94853 | AT25: 1.015e+10
A26: 2017 | B26: 23272.185 | C26: =[1]Data!$S419 -> 1022513.2 | D26: 27761.427 | E26: 16.562707 | F26: =DATA!F26*C26/100 -> 160534.58 | G26: 227802.94 | H26: =F26-G26 -> -67268.361 | J26: 5.5314409e+10 | K26: 8176.8668 | L26: =[1]Data!$S1679 -> 91522.484 | M26: 8654.193 | N26: 6.91 | O26: =DATA!N26*Complete!L26/100 -> 22331.486 | P26: 11802.576 | Q26: =O26-P26 -> 10528.91 | R26: 2.8227581 | S26: 1.0245969e+10 | T26: 11413.08 | U26: =[1]Data!$S3709 -> 191572.67 | V26: 16008.865 | W26: 1 | X26: =U26*DATA!V26/100 -> 36973.526 | Y26: 28058.449 | Z26: =X26-Y26 -> 8915.0763 | AA26: 0.41733559 | AB26: 2.1696979e+09 | AC26: 5654.6306 | AD26: =[1]Data!$S8819 -> 36103.945 | AE26: 7460.8417 | AF26: 30.050941 | AG26: =AD26*DATA!AD26/100 -> 8051.1798 | AH26: 7674.8985 | AI26: =AG26-AH26 -> 376.28129 | AJ26: 3.8506717 | AK26: 2.7577856e+09 | AL26: 434.26075 | AM26: =[1]Data!$S12389 -> 12768.345 | AN26: 439.55311 | AO26: 607.68822 | AP26: =AM26*DATA!AL26/100 -> #VALUE! | AQ26: 2751.2272 | AR26: =AP26-AQ26 -> #VALUE! | AT26: 9.7940621e+09
A27: 2018 | B27: 22477.7 | C27: =[1]Data!$S420 -> 997136.62 | D27: 26936.097 | E27: 28.094992 | F27: =DATA!F27*C27/100 -> 144584.81 | G27: 216377.12 | H27: =F27-G27 -> -71792.314 | J27: 6.6221502e+10 | K27: 8401.9087 | L27: =[1]Data!$S1680 -> 95388.062 | M27: 8801.2569 | N27: 6.91 | O27: =DATA!N27*Complete!L27/100 -> 22606.971 | P27: 12365.038 | Q27: =O27-P27 -> 10241.933 | R27: 2.2720599 | S27: 8.9296142e+09 | T27: 11357.911 | U27: =[1]Data!$S3710 -> 194042.61 | V27: 15843.318 | W27: 1 | X27: =U27*DATA!V27/100 -> 39002.564 | Y27: 28953.246 | Z27: =X27-Y27 -> 10049.318 | AA27: -0.22410325 | AB27: 2.158694e+09 | AC27: 5363.4982 | AD27: =[1]Data!$S8820 -> 34677.703 | AE27: 7200.1195 | AF27: 31.553212 | AG27: =AD27*DATA!AD27/100 -> 7525.0616 | AH27: 7783.2195 | AI27: =AG27-AH27 -> -258.15794 | AJ27: 4.9472373 | AK27: 2.2611434e+09 | AL27: 355.27981 | AM27: =[1]Data!$S12390 -> 10263.01 | AN27: 363.90051 | AO27: 388549.29 | AP27: =AM27*DATA!AL27/100 -> #VALUE! | AQ27: 2159.0286 | AR27: =AP27-AQ27 -> #VALUE!
A28: 2019 | B28: 21785.49 | C28: =[1]Data!$S421 -> 975569 | D28: 25704.775 | E28: 48.147892 | F28: =DATA!F28*C28/100 -> 142433.07 | G28: 218940.36 | H28: =F28-G28 -> -76507.286 | J28: 4.4880566e+10 | K28: 8468.8332 | L28: =[1]Data!$S1681 -> 97502.523 | M28: 8767.5343 | N28: 6.91 | O28: =DATA!N28*Complete!L28/100 -> 23010.596 | P28: 12882.094 | Q28: =O28-P28 -> 10128.501 | R28: 1.839545 | S28: 6.4554499e+09 | T28: 11174.779 | U28: =[1]Data!$S3711 -> 194146.83 | V28: 15701.851 | W28: 1 | X28: =U28*DATA!V28/100 -> 37858.631 | Y28: 28651.72 | Z28: =X28-Y28 -> 9206.9117 | AA28: 0.26601252 | AB28: 2.9402351e+09 | AC28: 5092.4409 | AD28: =[1]Data!$S8821 -> 33332.582 | AE28: 6912.0172 | AF28: 33.121745 | AG28: =AD28*DATA!AD28/100 -> 8033.1523 | AH28: 7805.9036 | AI28: =AG28-AH28 -> 227.24862 | AJ28: 5.3762899 | AK28: 2.3974447e+09 | AL28: 233.9387 | AM28: =[1]Data!$S12391 -> 6670.9561 | AN28: 244.47438 | AO28: 76369942 | AP28: =AM28*DATA!AL28/100 -> #VALUE! | AQ28: 1403.4667 | AR28: =AP28-AQ28 -> #VALUE!
A29: 2020 | B29: 0 | C29: =[1]Data!$S422 -> 0 | J29: 3.9403735e+10 | R29: 0.94074215 | S29: 5.2472347e+09 | AA29: -0.33887239 | AB29: 6.5694605e+09 | AJ29: 3.6818134 | AK29: 3.2119034e+09
A30: 2021 | B30: 0 | C30: =[1]Data!$S423 -> 0

Sheet ARG
A1: YEAR | B1: RGDP | C1: RGDP_CAP | D1: REAL_WAGE | E1: GOV_SPENDING | F1: DEFICIT | G1: INFLATION | H1: RESERVES | I1: NX_ENERGY
A2: =DATA!A4 -> 1995 | B2: =Complete!C4 -> 595788.81 | C2: =Complete!B4 -> 17106.521 | D2: =Complete!D4 -> 19830.379 | E2: =DATA!G4 -> 15 | F2: =Complete!H4 -> -16759.698 | G2: 1.61 | H2: =Complete!J4 -> 1.5979454e+10 | I2: -516.6
A3: =DATA!A5 -> 1996 | B3: =Complete!C5 -> 628716.12 | C3: =Complete!B5 -> 17837.753 | D3: =Complete!D5 -> 19009.441 | E3: =DATA!G5 -> 15 | F3: =Complete!H5 -> -60270.474 | G3: 0.05 | H3: =Complete!J5 -> 1.9719017e+10 | I3: -645.7
A4: =DATA!A6 -> 1997 | B4: =Complete!C6 -> 679711.62 | C4: =Complete!B6 -> 19062.272 | D4: =Complete!D6 -> 19006.541 | E4: =DATA!G6 -> 14 | F4: =Complete!H6 -> -41632.771 | G4: 0.33 | H4: =Complete!J6 -> 2.24246e+10 | I4: -737.7
A5: =DATA!A7 -> 1998 | B5: =Complete!C7 -> 705881.75 | C5: =Complete!B7 -> 19573.324 | D5: =Complete!D7 -> 19539.698 | E5: =DATA!G7 -> 14 | F5: =Complete!H7 -> -30844.039 | G5: 0.85 | H5: =Complete!J7 -> 2.4855741e+10 | I5: -757.9
A6: =DATA!A8 -> 1999 | B6: =Complete!C8 -> 681984.44 | C6: =Complete!B8 -> 18701.301 | D6: =Complete!D8 -> 19835.144 | E6: =DATA!G8 -> 16 | F6: =Complete!H8 -> -26963.085 | G6: -1.8104551 | H6: =Complete!J8 -> 2.6350163e+10 | I6: -780.9
A7: =DATA!A9 -> 2000 | B7: =Complete!C9 -> 676603.69 | C7: =Complete!B9 -> 18350.671 | D7: =Complete!D9 -> 19459.987 | E7: =DATA!G9 -> 16 | F7: =Complete!H9 -> -15244.854 | G7: -0.72960532 | H7: =Complete!J9 -> 2.5152117e+10 | I7: -866.5
A8: =DATA!A10 -> 2001 | B8: =Complete!C10 -> 646773.31 | C8: =Complete!B10 -> 17351.093 | D8: =Complete!D10 -> 19145.558 | E8: =DATA!G10 -> 16 | F8: =Complete!H10 -> -12889.238 | G8: -1.5465389 | H8: =Complete!J10 -> 1.4555553e+10 | I8: -1063.6
A9: =DATA!A11 -> 2002 | B9: =Complete!C11 -> 576310.62 | C9: =Complete!B11 -> 15294.158 | D9: =Complete!D11 -> 13644.503 | E9: =DATA!G11 -> 13 | F9: =Complete!H11 -> -16634.488 | G9: 40.946524 | H9: =Complete!J11 -> 1.0492425e+10 | I9: -1054.7
A10: =DATA!A12 -> 2003 | B10: =Complete!C12 -> 627239.5 | C10: =Complete!B12 -> 16468.223 | D10: =Complete!D12 -> 13826.707 | E10: =DATA!G12 -> 14 | F10: =Complete!H12 -> 2163.8668 | G10: 3.6610312 | H10: =Complete!J12 -> 1.4157284e+10 | I10: -1030.4
A11: =DATA!A13 -> 2004 | B11: =Complete!C13 -> 683876.5 | C11: =Complete!B13 -> 17766.731 | D11: =Complete!D13 -> 14811.075 | E11: =DATA!G13 -> 13 | F11: =Complete!H13 -> 22385.261 | G11: 6.0967696 | H11: =Complete!J13 -> 1.9659592e+10 | I11: -793.1
A12: =DATA!A14 -> 2005 | B12: =Complete!C14 -> 744411 | C12: =Complete!B14 -> 19140.008 | D12: =Complete!D14 -> 16020.629 | E12: =DATA!G14 -> 15 | F12: =Complete!H14 -> 28942.618 | G12: 12.328987 | H12: =Complete!J14 -> 2.8081719e+10 | I12: -675.8
A13: =DATA!A15 -> 2006 | B13: =Complete!C15 -> 804314.81 | C13: =Complete!B15 -> 20471.298 | D13: =Complete!D15 -> 17545.915 | E13: =DATA!G15 -> 15 | F13: =Complete!H15 -> 27680.056 | G13: 9.8390284 | H13: =Complete!J15 -> 3.2022297e+10 | I13: -553.9
... A26: =DATA!A28 -> 2019 | B26: =Complete!C28 -> 975569 | C26: =Complete!B28 -> 21785.49 | D26: =Complete!D28 -> 25704.775 | E26: =DATA!G28 -> 22 | F26: =Complete!H28 -> -76507.286 | G26: 53.97586 | H26: =Complete!J28 -> 4.4880566e+10 | I26: 87.9

Sheet ECU
A1: YEAR | B1: RGDP | C1: RGDP_CAP | D1: REAL_WAGE | E1: GOV_SPENDING | F1: DEFICIT | G1: INFLATION | H1: RESERVES | I1: NX_ENERGY
A2: =DATA!A11 -> 2002 | B2: =Complete!U11 -> 110287.85 | C2: =Complete!T11 -> 8391.0789 | D2: =Complete!V11 -> 10485.908 | E2: =DATA!W11 -> 15 | F2: =Complete!Z11 -> 342.73568 | G2: =Complete!AA11 -> 12.484019 | H2: =Complete!AB11 -> 1.0044028e+09
A3: =DATA!A12 -> 2003 | B3: =Complete!U12 -> 113290.86 | C3: =Complete!T12 -> 8473.7164 | D3: =Complete!V12 -> 10942.61 | E3: =DATA!W12 -> 15 | F3: =Complete!Z12 -> 484.69292 | G3: =Complete!AA12 -> 7.92941 | H3: =Complete!AB12 -> 1.1653404e+09
A4: =DATA!A13 -> 2004 | B4: =Complete!U13 -> 122593.2 | C4: =Complete!T13 -> 9016.6002 | D4: =Complete!V13 -> 11354.863 | E4: =DATA!W13 -> 15 | F4: =Complete!Z13 -> 2060.7488 | G4: =Complete!AA13 -> 2.7421813 | H4: =Complete!AB13 -> 1.439914e+09
A5: =DATA!A14 -> 2005 | B5: =Complete!U14 -> 129079.98 | C5: =Complete!T14 -> 9336.1357 | D5: =Complete!V14 -> 12042.493 | E5: =DATA!W14 -> 14 | F5: =Complete!Z14 -> 4285.072 | G5: =Complete!AA14 -> 2.4077698 | H5: =Complete!AB14 -> 2.1479446e+09
A6: =DATA!A15 -> 2006 | B6: =Complete!U15 -> 134764 | C6: =Complete!T15 -> 9585.3417 | D6: =Complete!V15 -> 12602.422 | E6: =DATA!W15 -> 14 | F6: =Complete!Z15 -> 5920.7715 | G6: =Complete!AA15 -> 3.2987485 | H6: =Complete!AB15 -> 2.0264803e+09
A7: =DATA!A16 -> 2007 | B7: =Complete!U16 -> 137715.47 | C7: =Complete!T16 -> 9632.7716 | D7: =Complete!V16 -> 12831.094 | E7: =DATA!W16 -> 16 | F7: =Complete!Z16 -> 6550.7918 | G7: =Complete!AA16 -> 2.2761848 | H7: =Complete!AB16 -> 3.520673e+09
A8: =DATA!A17 -> 2008 | B8: =Complete!U17 -> 146470.22 | C8: =Complete!T17 -> 10076.558 | D8: =Complete!V17 -> 13825.823 | E8: =DATA!W17 -> 21 | F8: =Complete!Z17 -> 6311.6881 | G8: =Complete!AA17 -> 8.4000959 | H8: =Complete!AB17 -> 4.4728546e+09
A9: =DATA!A18 -> 2009 | B9: =Complete!U18 -> 147299.97 | C9: =Complete!T18 -> 9969.9297 | D9: =Complete!V18 -> 14070.383 | E9: =DATA!W18 -> 23 | F9: =Complete!Z18 -> 5069.8475 | G9: =Complete!AA18 -> 5.1599683 | H9: =Complete!AB18 -> 3.7921222e+09
A10: =DATA!A19 -> 2010 | B10: =Complete!U19 -> 152492.72 | C10: =Complete!T19 -> 10158.652 | D10: =Complete!V19 -> 14556.456 | E10: =DATA!W19 -> 23 | F10: =Complete!Z19 -> 5953.2713 | G10: =Complete!AA19 -> 3.5543773 | H10: =Complete!AB19 -> 2.6224934e+09
A11: =DATA!A20 -> 2011 | B11: =Complete!U20 -> 164491.06 | C11: =Complete!T20 -> 10790.627 | D11: =Complete!V20 -> 15682.955 | E11: =DATA!W20 -> 23 | F11: =Complete!Z20 -> 8480.3514 | G11: =Complete!AA20 -> 4.4745327 | H11: =Complete!AB20 -> 2.9579994e+09
A12: =DATA!A21 -> 2012 | B12: =Complete!U21 -> 173771.59 | C12: =Complete!T21 -> 11229.835 | D12: =Complete!V21 -> 16524.836 | E12: =DATA!W21 -> 24 | F12: =Complete!Z21 -> 13902.713 | G12: =Complete!AA21 -> 5.1017218 | H12: =Complete!AB21 -> 2.4860361e+09
A13: =DATA!A22 -> 2013 | B13: =Complete!U22 -> 182367.22 | C13: =Complete!T22 -> 11610.219 | D13: =Complete!V22 -> 16533.926 | E13: =DATA!W22 -> 27 | F13: =Complete!Z22 -> 12960.179 | G13: =Complete!AA22 -> 2.7217758 | H13: =Complete!AB22 -> 4.3458403e+09
... A19: =DATA!A28 -> 2019 | B19: =Complete!U28 -> 194146.83 | C19: =Complete!T28 -> 11174.779 | D19: =Complete!V28 -> 15701.851 | E19: =DATA!W28 -> 28 | F19: =Complete!Z28 -> 9206.9117 | G19: =Complete!AA28 -> 0.26601252 | H19: =Complete!AB28 -> 2.9402351e+09
A20: =DATA!A29 -> 2020 | E20: =DATA!W29 -> 28 | G20: =Complete!AA29 -> -0.33887239 | H20: =Complete!AB29 -> 6.5694605e+09
A21: =DATA!A30 -> 2021

Sheet Comparisons
A1: Period | B1: GDP Per Capita | H1: Period | I1: =Complete!AD3 -> GDP | O1: Period | P1: Real Wages | V1: Period | W1: Gov Spending
A2: Period | B2: Argentina | C2: Bolivia | D2: Ecuador | E2: Nicaragua | F2: Venezuela | H2: Period | I2: Argentina | J2: Bolivia | K2: Ecuador | L2: Nicaragua | M2: Venezuela | O2: Period | P2: Argentina | Q2: Bolivia | R2: Ecuador | S2: Nicaragua | T2: Venezuela | V2: Period | W2: Argentina | X2: Bolivia | Y2: Ecuador | Z2: Nicaragua | AA2: Venezuela
A3: t-3 | B3: 100 | C3: 100 | D3: 100 | E3: 100 | F3: 100 | H3: t-3 | I3: 100 | J3: 100 | K3: 100 | L3: 100 | M3: 100 | O3: t-3 | P3: 100 | Q3: 100 | R3: 100 | S3: 100 | T3: 100 | V3: t-3 | W3: 100 | X3: 100 | Y3: 100 | Z3: 100 | AA3: 100
A4: t-2 | B4: =Complete!B10/Complete!B$9*100 -> 94.552908 | C4: =Complete!K13/Complete!K$12*100 -> 102.29848 | D4: =Complete!T14/Complete!T$13*100 -> 103.54386 | E4: =Complete!AC14/Complete!AC$13*100 -> 102.8682 | F4: =Complete!AL6/Complete!AL$5*100 -> 104.26522 | H4: t-2 | I4: =Complete!C10/Complete!C$9*100 -> 95.59116 | J4: =Complete!L13/Complete!L$12*100 -> 104.17329 | K4: =Complete!U14/Complete!U$13*100 -> 105.29131 | L4: =Complete!AD14/Complete!AD$13*100 -> 104.28239 | M4: =Complete!AM6/Complete!AM$5*100 -> 106.37092 | O4: t-2 | P4: =Complete!D10/Complete!D$9*100 -> 98.38423 | Q4: =Complete!M13/Complete!M$12*100 -> 94.331044 | R4: =Complete!V14/Complete!V$13*100 -> 106.05582 | S4: =Complete!AE14/Complete!AE$13*100 -> 100.48666 | T4: =Complete!AM6/Complete!AM$5*100 -> 106.37092 | V4: t-2 | W4: =Complete!G10/Complete!G9*100 -> 91.131514 | X4: =Complete!P13/Complete!P$12*100 -> 97.06078 | Y4: =Complete!Y14/Complete!Y$13*100 -> 94.508075 | Z4: =Complete!AH14/Complete!AH$13*100 -> 108.6847 | AA4: =Complete!AQ6/Complete!AQ$5*100 -> 98.797478
A5: t-1 | B5: =Complete!B11/Complete!B$9*100 -> 83.343862 | C5: =Complete!F14/Complete!F$12*100 -> 136.57677 | D5: =Complete!T15/Complete!T$13*100 -> 106.30772 | E5: =Complete!AC15/Complete!AC$13*100 -> 105.68059 | F5: =Complete!AL7/Complete!AL$5*100 -> 102.54742 | H5: t-1 | I5: =Complete!C11/Complete!C$9*100 -> 85.176986 | J5: =Complete!L14/Complete!L$12*100 -> 108.77907 | K5: =Complete!U15/Complete!U$13*100 -> 109.9278 | L5: =Complete!AD15/Complete!AD$13*100 -> 108.61227 | M5: =Complete!AM7/Complete!AM$5*100 -> 106.68362 | O5: t-1 | P5: =Complete!D11/Complete!D$9*100 -> 70.115685 | Q5: =Complete!M14/Complete!M$12*100 -> 94.407034 | R5: =Complete!V15/Complete!V$13*100 -> 110.987 | S5: =Complete!AE15/Complete!AE$13*100 -> 101.84939 | T5: =Complete!AM7/Complete!AM$5*100 -> 106.68362 | V5: t-1 | W5: =Complete!G11/Complete!G10*100 -> 90.383511 | X5: =Complete!P14/Complete!P$12*100 -> 95.380723 | Y5: =Complete!Y15/Complete!Y$13*100 -> 96.952108 | Z5: =Complete!AH15/Complete!AH$13*100 -> 114.83529 | AA5: =Complete!AQ7/Complete!AQ$5*100 -> 93.891634
A6: t | B6: =Complete!B12/Complete!B$9*100 -> 89.741802 | C6: =Complete!F15/Complete!F$12*100 -> 149.60271 | D6: =Complete!T16/Complete!T$13*100 -> 106.83374 | E6: =Complete!AC16/Complete!AC$13*100 -> 109.5298 | F6: =Complete!AL8/Complete!AL$5*100 -> 94.591824 | H6: t | I6: =Complete!C12/Complete!C$9*100 -> 92.704121 | J6: =Complete!L15/Complete!L$12*100 -> 113.99735 | K6: =Complete!U16/Complete!U$13*100 -> 112.33533 | L6: =Complete!AD16/Complete!AD$13*100 -> 114.12582 | M6: =Complete!AM8/Complete!AM$5*100 -> 100.31403 | O6: t | P6: =Complete!D12/Complete!D$9*100 -> 71.051988 | Q6: =Complete!M15/Complete!M$12*100 -> 89.199697 | R6: =Complete!V16/Complete!V$13*100 -> 113.00087 | S6: =Complete!AE16/Complete!AE$13*100 -> 104.20493 | T6: =Complete!AM8/Complete!AM$5*100 -> 100.31403 | V6: t | W6: =Complete!G12/Complete!G11*100 -> 97.454582 | X6: =Complete!P15/Complete!P$12*100 -> 92.814296 | Y6: =Complete!Y16/Complete!Y$13*100 -> 101.46662 | Z6: =Complete!AH16/Complete!AH$13*100 -> 116.04957 | AA6: =Complete!AQ8/Complete!AQ$5*100 -> 72.542229
